Workbook

Sheet Dus-intors
A1: București (OTP/BBU) ⇄ Europa de Vest – 26/27.11 → 30.11/01.12.2026 – prețuri pe persoană, RON (completează celulele galbene)
A2: Google Flights caută din BUH = OTP + Băneasa. Totalul minim și zilele se calculează automat. Exemplu Memmingen: pune prețul Ryanair pe care l-ai găsit în F/G și H/I.
A3: Cod | B3: Destinație | C3: Țară | D3: Companii (din OTP) | E3: Târg de Crăciun / note | F3: DUS 26.11 | G3: DUS 27.11 | H3: ÎNTORS 30.11 | I3: ÎNTORS 01.12 | J3: Cel mai ieftin dus | K3: Cel mai ieftin întors | L3: TOTAL minim | M3: Zile dus→întors (cele mai ieftine) | N3: Rută verificată? (da/nu) | O3: Google Flights dus 26 | P3: Google Flights dus 27 | Q3: Google Flights întors 30 | R3: Google Flights întors 01 | S3: Ryanair dus 26 | T3: Wizz dus 26
A4: FMM | B4: Memmingen (München/Allgäu) | C4: DE | D4: Ryanair, Wizz | E4: München Christkindlmarkt + Augsburg; tren ~1h30 spre München | J4: =IF(COUNT(F4:G4)=0,"",MIN(F4:G4)) | K4: =IF(COUNT(H4:I4)=0,"",MIN(H4:I4)) | L4: =IF(OR(J4="",K4=""),"",J4+K4) | M4: =IF(L4="","",IF(F4=J4,"26.11","27.11")&" → "&IF(H4=K4,"30.11","01.12")) | O4: deschide | P4: deschide | Q4: deschide | R4: deschide | S4: deschide | T4: deschide
A5: MUC | B5: München | C5: DE | D5: Lufthansa, TAROM | E5: Marienplatz, Residenz; aeroport scump dar direct | J5: =IF(COUNT(F5:G5)=0,"",MIN(F5:G5)) | K5: =IF(COUNT(H5:I5)=0,"",MIN(H5:I5)) | L5: =IF(OR(J5="",K5=""),"",J5+K5) | M5: =IF(L5="","",IF(F5=J5,"26.11","27.11")&" → "&IF(H5=K5,"30.11","01.12")) | O5: deschide | P5: deschide | Q5: deschide | R5: deschide | S5: deschide | T5: deschide
A6: NUE | B6: Nürnberg | C6: DE | D6: Wizz/Ryanair (de verificat) | E6: Christkindlesmarkt – cel mai faimos; se deschide vineri 27.11.2026 | J6: =IF(COUNT(F6:G6)=0,"",MIN(F6:G6)) | K6: =IF(COUNT(H6:I6)=0,"",MIN(H6:I6)) | L6: =IF(OR(J6="",K6=""),"",J6+K6) | M6: =IF(L6="","",IF(F6=J6,"26.11","27.11")&" → "&IF(H6=K6,"30.11","01.12")) | O6: deschide | P6: deschide | Q6: deschide | R6: deschide | S6: deschide | T6: deschide
A7: FKB | B7: Karlsruhe/Baden-Baden | C7: DE | D7: Wizz/Ryanair (de verificat) | E7: Baden-Baden, Karlsruhe; Strasbourg la ~1h | J7: =IF(COUNT(F7:G7)=0,"",MIN(F7:G7)) | K7: =IF(COUNT(H7:I7)=0,"",MIN(H7:I7)) | L7: =IF(OR(J7="",K7=""),"",J7+K7) | M7: =IF(L7="","",IF(F7=J7,"26.11","27.11")&" → "&IF(H7=K7,"30.11","01.12")) | O7: deschide | P7: deschide | Q7: deschide | R7: deschide | S7: deschide | T7: deschide
A8: HHN | B8: Frankfurt Hahn | C8: DE | D8: Wizz/Ryanair (de verificat) | E8: Rüdesheim, Mainz; Frankfurt la ~1h45 cu autocarul | J8: =IF(COUNT(F8:G8)=0,"",MIN(F8:G8)) | K8: =IF(COUNT(H8:I8)=0,"",MIN(H8:I8)) | L8: =IF(OR(J8="",K8=""),"",J8+K8) | M8: =IF(L8="","",IF(F8=J8,"26.11","27.11")&" → "&IF(H8=K8,"30.11","01.12")) | O8: deschide | P8: deschide | Q8: deschide | R8: deschide | S8: deschide | T8: deschide
A9: FRA | B9: Frankfurt | C9: DE | D9: Lufthansa, TAROM | E9: Römerberg; acces rapid spre Heidelberg | J9: =IF(COUNT(F9:G9)=0,"",MIN(F9:G9)) | K9: =IF(COUNT(H9:I9)=0,"",MIN(H9:I9)) | L9: =IF(OR(J9="",K9=""),"",J9+K9) | M9: =IF(L9="","",IF(F9=J9,"26.11","27.11")&" → "&IF(H9=K9,"30.11","01.12")) | O9: deschide | P9: deschide | Q9: deschide | R9: deschide | S9: deschide | T9: deschide
A10: CGN | B10: Köln | C10: DE | D10: Wizz | E10: 7 târguri în oraș, Domul; Düsseldorf/Aachen aproape | J10: =IF(COUNT(F10:G10)=0,"",MIN(F10:G10)) | K10: =IF(COUNT(H10:I10)=0,"",MIN(H10:I10)) | L10: =IF(OR(J10="",K10=""),"",J10+K10) | M10: =IF(L10="","",IF(F10=J10,"26.11","27.11")&" → "&IF(H10=K10,"30.11","01.12")) | O10: deschide | P10: deschide | Q10: deschide | R10: deschide | S10: deschide | T10: deschide
A11: DTM | B11: Dortmund | C11: DE | D11: Wizz | E11: Cel mai mare brad de Crăciun; Köln/Münster aproape | J11: =IF(COUNT(F11:G11)=0,"",MIN(F11:G11)) | K11: =IF(COUNT(H11:I11)=0,"",MIN(H11:I11)) | L11: =IF(OR(J11="",K11=""),"",J11+K11) | M11: =IF(L11="","",IF(F11=J11,"26.11","27.11")&" → "&IF(H11=K11,"30.11","01.12")) | O11: deschide | P11: deschide | Q11: deschide | R11: deschide | S11: deschide | T11: deschide
A12: HAM | B12: Hamburg | C12: DE | D12: Wizz/Ryanair (de verificat) | E12: Rathausmarkt; Lübeck la 45 min | J12: =IF(COUNT(F12:G12)=0,"",MIN(F12:G12)) | K12: =IF(COUNT(H12:I12)=0,"",MIN(H12:I12)) | L12: =IF(OR(J12="",K12=""),"",J12+K12) | M12: =IF(L12="","",IF(F12=J12,"26.11","27.11")&" → "&IF(H12=K12,"30.11","01.12")) | O12: deschide | P12: deschide | Q12: deschide | R12: deschide | S12: deschide | T12: deschide
A13: BER | B13: Berlin | C13: DE | D13: Wizz, Ryanair (redus) | E13: Gendarmenmarkt, Charlottenburg | J13: =IF(COUNT(F13:G13)=0,"",MIN(F13:G13)) | K13: =IF(COUNT(H13:I13)=0,"",MIN(H13:I13)) | L13: =IF(OR(J13="",K13=""),"",J13+K13) | M13: =IF(L13="","",IF(F13=J13,"26.11","27.11")&" → "&IF(H13=K13,"30.11","01.12")) | O13: deschide | P13: deschide | Q13: deschide | R13: deschide | S13: deschide | T13: deschide
A14: STR | B14: Stuttgart | C14: DE | D14: Eurowings/TAROM (de verificat) | E14: Stuttgarter Weihnachtsmarkt, Esslingen (medieval) | J14: =IF(COUNT(F14:G14)=0,"",MIN(F14:G14)) | K14: =IF(COUNT(H14:I14)=0,"",MIN(H14:I14)) | L14: =IF(OR(J14="",K14=""),"",J14+K14) | M14: =IF(L14="","",IF(F14=J14,"26.11","27.11")&" → "&IF(H14=K14,"30.11","01.12")) | O14: deschide | P14: deschide | Q14: deschide | R14: deschide | S14: deschide | T14: deschide
A15: BSL | B15: Basel/Mulhouse | C15: CH/FR | D15: Wizz | E15: Basel + Colmar (40 min) + Strasbourg (1h15) | J15: =IF(COUNT(F15:G15)=0,"",MIN(F15:G15)) | K15: =IF(COUNT(H15:I15)=0,"",MIN(H15:I15)) | L15: =IF(OR(J15="",K15=""),"",J15+K15) | M15: =IF(L15="","",IF(F15=J15,"26.11","27.11")&" → "&IF(H15=K15,"30.11","01.12")) | O15: deschide | P15: deschide | Q15: deschide | R15: deschide | S15: deschide | T15: deschide
... A39: CPH | B39: Copenhaga | C39: DK | D39: Wizz (de verificat) | E39: Tivoli Christmas | J39: =IF(COUNT(F39:G39)=0,"",MIN(F39:G39)) | K39: =IF(COUNT(H39:I39)=0,"",MIN(H39:I39)) | L39: =IF(OR(J39="",K39=""),"",J39+K39) | M39: =IF(L39="","",IF(F39=J39,"26.11","27.11")&" → "&IF(H39=K39,"30.11","01.12")) | O39: deschide | P39: deschide | Q39: deschide | R39: deschide | S39: deschide | T39: deschide

Sheet Combinatii (alt oras)
A1: Dus într-un oraș, întors din altul (open-jaw) – prețurile se preiau automat din foaia Dus-intors
A2: Adaugă costul trenului/autobuzului între orașe în coloana galbenă. Combinația merită doar dacă TOTAL < totalul dus-întors simplu.
A3: Dus în | B3: Oraș dus | C3: Întors din | D3: Oraș întors | E3: Legătură terestră | F3: Dus 26.11 | G3: Dus 27.11 | H3: Întors 30.11 | I3: Întors 01.12 | J3: Cost tren/bus (RON) | K3: TOTAL minim | L3: Zile
A4: FMM | B4: Memmingen (München/Allgäu) | C4: MUC | D4: München | E4: tren ~1h30 (München e și ținta) | F4: =IFERROR(IF(INDEX('Dus-intors'!F:F,MATCH("FMM",'Dus-intors'!A:A,0))="","",INDEX('Dus-intors'!F:F,MATCH("FMM",'Dus-intors'!A:A,0))),"") | G4: =IFERROR(IF(INDEX('Dus-intors'!G:G,MATCH("FMM",'Dus-intors'!A:A,0))="","",INDEX('Dus-intors'!G:G,MATCH("FMM",'Dus-intors'!A:A,0))),"") | H4: =IFERROR(IF(INDEX('Dus-intors'!H:H,MATCH("MUC",'Dus-intors'!A:A,0))="","",INDEX('Dus-intors'!H:H,MATCH("MUC",'Dus-intors'!A:A,0))),"") | I4: =IFERROR(IF(INDEX('Dus-intors'!I:I,MATCH("MUC",'Dus-intors'!A:A,0))="","",INDEX('Dus-intors'!I:I,MATCH("MUC",'Dus-intors'!A:A,0))),"") | K4: =IF(OR(COUNT(F4:G4)=0,COUNT(H4:I4)=0),"",MIN(F4:G4)+MIN(H4:I4)+N(J4)) | L4: =IF(K4="","",IF(F4=MIN(F4:G4),"26.11","27.11")&" → "&IF(H4=MIN(H4:I4),"30.11","01.12"))
A5: MUC | B5: München | C5: FMM | D5: Memmingen (München/Allgäu) | E5: tren ~1h30 | F5: =IFERROR(IF(INDEX('Dus-intors'!F:F,MATCH("MUC",'Dus-intors'!A:A,0))="","",INDEX('Dus-intors'!F:F,MATCH("MUC",'Dus-intors'!A:A,0))),"") | G5: =IFERROR(IF(INDEX('Dus-intors'!G:G,MATCH("MUC",'Dus-intors'!A:A,0))="","",INDEX('Dus-intors'!G:G,MATCH("MUC",'Dus-intors'!A:A,0))),"") | H5: =IFERROR(IF(INDEX('Dus-intors'!H:H,MATCH("FMM",'Dus-intors'!A:A,0))="","",INDEX('Dus-intors'!H:H,MATCH("FMM",'Dus-intors'!A:A,0))),"") | I5: =IFERROR(IF(INDEX('Dus-intors'!I:I,MATCH("FMM",'Dus-intors'!A:A,0))="","",INDEX('Dus-intors'!I:I,MATCH("FMM",'Dus-intors'!A:A,0))),"") | K5: =IF(OR(COUNT(F5:G5)=0,COUNT(H5:I5)=0),"",MIN(F5:G5)+MIN(H5:I5)+N(J5)) | L5: =IF(K5="","",IF(F5=MIN(F5:G5),"26.11","27.11")&" → "&IF(H5=MIN(H5:I5),"30.11","01.12"))
A6: FMM | B6: Memmingen (München/Allgäu) | C6: NUE | D6: Nürnberg | E6: tren ~3h prin München/Augsburg | F6: =IFERROR(IF(INDEX('Dus-intors'!F:F,MATCH("FMM",'Dus-intors'!A:A,0))="","",INDEX('Dus-intors'!F:F,MATCH("FMM",'Dus-intors'!A:A,0))),"") | G6: =IFERROR(IF(INDEX('Dus-intors'!G:G,MATCH("FMM",'Dus-intors'!A:A,0))="","",INDEX('Dus-intors'!G:G,MATCH("FMM",'Dus-intors'!A:A,0))),"") | H6: =IFERROR(IF(INDEX('Dus-intors'!H:H,MATCH("NUE",'Dus-intors'!A:A,0))="","",INDEX('Dus-intors'!H:H,MATCH("NUE",'Dus-intors'!A:A,0))),"") | I6: =IFERROR(IF(INDEX('Dus-intors'!I:I,MATCH("NUE",'Dus-intors'!A:A,0))="","",INDEX('Dus-intors'!I:I,MATCH("NUE",'Dus-intors'!A:A,0))),"") | K6: =IF(OR(COUNT(F6:G6)=0,COUNT(H6:I6)=0),"",MIN(F6:G6)+MIN(H6:I6)+N(J6)) | L6: =IF(K6="","",IF(F6=MIN(F6:G6),"26.11","27.11")&" → "&IF(H6=MIN(H6:I6),"30.11","01.12"))
A7: NUE | B7: Nürnberg | C7: FMM | D7: Memmingen (München/Allgäu) | E7: tren ~3h | F7: =IFERROR(IF(INDEX('Dus-intors'!F:F,MATCH("NUE",'Dus-intors'!A:A,0))="","",INDEX('Dus-intors'!F:F,MATCH("NUE",'Dus-intors'!A:A,0))),"") | G7: =IFERROR(IF(INDEX('Dus-intors'!G:G,MATCH("NUE",'Dus-intors'!A:A,0))="","",INDEX('Dus-intors'!G:G,MATCH("NUE",'Dus-intors'!A:A,0))),"") | H7: =IFERROR(IF(INDEX('Dus-intors'!H:H,MATCH("FMM",'Dus-intors'!A:A,0))="","",INDEX('Dus-intors'!H:H,MATCH("FMM",'Dus-intors'!A:A,0))),"") | I7: =IFERROR(IF(INDEX('Dus-intors'!I:I,MATCH("FMM",'Dus-intors'!A:A,0))="","",INDEX('Dus-intors'!I:I,MATCH("FMM",'Dus-intors'!A:A,0))),"") | K7: =IF(OR(COUNT(F7:G7)=0,COUNT(H7:I7)=0),"",MIN(F7:G7)+MIN(H7:I7)+N(J7)) | L7: =IF(K7="","",IF(F7=MIN(F7:G7),"26.11","27.11")&" → "&IF(H7=MIN(H7:I7),"30.11","01.12"))
A8: FMM | B8: Memmingen (München/Allgäu) | C8: SZG | D8: Salzburg | E8: tren ~3h; München–Salzburg 1h30 | F8: =IFERROR(IF(INDEX('Dus-intors'!F:F,MATCH("FMM",'Dus-intors'!A:A,0))="","",INDEX('Dus-intors'!F:F,MATCH("FMM",'Dus-intors'!A:A,0))),"") | G8: =IFERROR(IF(INDEX('Dus-intors'!G:G,MATCH("FMM",'Dus-intors'!A:A,0))="","",INDEX('Dus-intors'!G:G,MATCH("FMM",'Dus-intors'!A:A,0))),"") | H8: =IFERROR(IF(INDEX('Dus-intors'!H:H,MATCH("SZG",'Dus-intors'!A:A,0))="","",INDEX('Dus-intors'!H:H,MATCH("SZG",'Dus-intors'!A:A,0))),"") | I8: =IFERROR(IF(INDEX('Dus-intors'!I:I,MATCH("SZG",'Dus-intors'!A:A,0))="","",INDEX('Dus-intors'!I:I,MATCH("SZG",'Dus-intors'!A:A,0))),"") | K8: =IF(OR(COUNT(F8:G8)=0,COUNT(H8:I8)=0),"",MIN(F8:G8)+MIN(H8:I8)+N(J8)) | L8: =IF(K8="","",IF(F8=MIN(F8:G8),"26.11","27.11")&" → "&IF(H8=MIN(H8:I8),"30.11","01.12"))
A9: FMM | B9: Memmingen (München/Allgäu) | C9: BSL | D9: Basel/Mulhouse | E9: tren ~4h via Lindau/Zürich | F9: =IFERROR(IF(INDEX('Dus-intors'!F:F,MATCH("FMM",'Dus-intors'!A:A,0))="","",INDEX('Dus-intors'!F:F,MATCH("FMM",'Dus-intors'!A:A,0))),"") | G9: =IFERROR(IF(INDEX('Dus-intors'!G:G,MATCH("FMM",'Dus-intors'!A:A,0))="","",INDEX('Dus-intors'!G:G,MATCH("FMM",'Dus-intors'!A:A,0))),"") | H9: =IFERROR(IF(INDEX('Dus-intors'!H:H,MATCH("BSL",'Dus-intors'!A:A,0))="","",INDEX('Dus-intors'!H:H,MATCH("BSL",'Dus-intors'!A:A,0))),"") | I9: =IFERROR(IF(INDEX('Dus-intors'!I:I,MATCH("BSL",'Dus-intors'!A:A,0))="","",INDEX('Dus-intors'!I:I,MATCH("BSL",'Dus-intors'!A:A,0))),"") | K9: =IF(OR(COUNT(F9:G9)=0,COUNT(H9:I9)=0),"",MIN(F9:G9)+MIN(H9:I9)+N(J9)) | L9: =IF(K9="","",IF(F9=MIN(F9:G9),"26.11","27.11")&" → "&IF(H9=MIN(H9:I9),"30.11","01.12"))
A10: FMM | B10: Memmingen (München/Allgäu) | C10: FKB | D10: Karlsruhe/Baden-Baden | E10: tren ~3h via Ulm/Stuttgart | F10: =IFERROR(IF(INDEX('Dus-intors'!F:F,MATCH("FMM",'Dus-intors'!A:A,0))="","",INDEX('Dus-intors'!F:F,MATCH("FMM",'Dus-intors'!A:A,0))),"") | G10: =IFERROR(IF(INDEX('Dus-intors'!G:G,MATCH("FMM",'Dus-intors'!A:A,0))="","",INDEX('Dus-intors'!G:G,MATCH("FMM",'Dus-intors'!A:A,0))),"") | H10: =IFERROR(IF(INDEX('Dus-intors'!H:H,MATCH("FKB",'Dus-intors'!A:A,0))="","",INDEX('Dus-intors'!H:H,MATCH("FKB",'Dus-intors'!A:A,0))),"") | I10: =IFERROR(IF(INDEX('Dus-intors'!I:I,MATCH("FKB",'Dus-intors'!A:A,0))="","",INDEX('Dus-intors'!I:I,MATCH("FKB",'Dus-intors'!A:A,0))),"") | K10: =IF(OR(COUNT(F10:G10)=0,COUNT(H10:I10)=0),"",MIN(F10:G10)+MIN(H10:I10)+N(J10)) | L10: =IF(K10="","",IF(F10=MIN(F10:G10),"26.11","27.11")&" → "&IF(H10=MIN(H10:I10),"30.11","01.12"))
A11: FMM | B11: Memmingen (München/Allgäu) | C11: STR | D11: Stuttgart | E11: tren ~2h30 via Ulm | F11: =IFERROR(IF(INDEX('Dus-intors'!F:F,MATCH("FMM",'Dus-intors'!A:A,0))="","",INDEX('Dus-intors'!F:F,MATCH("FMM",'Dus-intors'!A:A,0))),"") | G11: =IFERROR(IF(INDEX('Dus-intors'!G:G,MATCH("FMM",'Dus-intors'!A:A,0))="","",INDEX('Dus-intors'!G:G,MATCH("FMM",'Dus-intors'!A:A,0))),"") | H11: =IFERROR(IF(INDEX('Dus-intors'!H:H,MATCH("STR",'Dus-intors'!A:A,0))="","",INDEX('Dus-intors'!H:H,MATCH("STR",'Dus-intors'!A:A,0))),"") | I11: =IFERROR(IF(INDEX('Dus-intors'!I:I,MATCH("STR",'Dus-intors'!A:A,0))="","",INDEX('Dus-intors'!I:I,MATCH("STR",'Dus-intors'!A:A,0))),"") | K11: =IF(OR(COUNT(F11:G11)=0,COUNT(H11:I11)=0),"",MIN(F11:G11)+MIN(H11:I11)+N(J11)) | L11: =IF(K11="","",IF(F11=MIN(F11:G11),"26.11","27.11")&" → "&IF(H11=MIN(H11:I11),"30.11","01.12"))
A12: FMM | B12: Memmingen (München/Allgäu) | C12: VIE | D12: Viena | E12: tren ~5h via München | F12: =IFERROR(IF(INDEX('Dus-intors'!F:F,MATCH("FMM",'Dus-intors'!A:A,0))="","",INDEX('Dus-intors'!F:F,MATCH("FMM",'Dus-intors'!A:A,0))),"") | G12: =IFERROR(IF(INDEX('Dus-intors'!G:G,MATCH("FMM",'Dus-intors'!A:A,0))="","",INDEX('Dus-intors'!G:G,MATCH("FMM",'Dus-intors'!A:A,0))),"") | H12: =IFERROR(IF(INDEX('Dus-intors'!H:H,MATCH("VIE",'Dus-intors'!A:A,0))="","",INDEX('Dus-intors'!H:H,MATCH("VIE",'Dus-intors'!A:A,0))),"") | I12: =IFERROR(IF(INDEX('Dus-intors'!I:I,MATCH("VIE",'Dus-intors'!A:A,0))="","",INDEX('Dus-intors'!I:I,MATCH("VIE",'Dus-intors'!A:A,0))),"") | K12: =IF(OR(COUNT(F12:G12)=0,COUNT(H12:I12)=0),"",MIN(F12:G12)+MIN(H12:I12)+N(J12)) | L12: =IF(K12="","",IF(F12=MIN(F12:G12),"26.11","27.11")&" → "&IF(H12=MIN(H12:I12),"30.11","01.12"))
A13: FMM | B13: Memmingen (München/Allgäu) | C13: INN | D13: Innsbruck | E13: tren ~3h via München | F13: =IFERROR(IF(INDEX('Dus-intors'!F:F,MATCH("FMM",'Dus-intors'!A:A,0))="","",INDEX('Dus-intors'!F:F,MATCH("FMM",'Dus-intors'!A:A,0))),"") | G13: =IFERROR(IF(INDEX('Dus-intors'!G:G,MATCH("FMM",'Dus-intors'!A:A,0))="","",INDEX('Dus-intors'!G:G,MATCH("FMM",'Dus-intors'!A:A,0))),"") | H13: =IFERROR(IF(INDEX('Dus-intors'!H:H,MATCH("INN",'Dus-intors'!A:A,0))="","",INDEX('Dus-intors'!H:H,MATCH("INN",'Dus-intors'!A:A,0))),"") | I13: =IFERROR(IF(INDEX('Dus-intors'!I:I,MATCH("INN",'Dus-intors'!A:A,0))="","",INDEX('Dus-intors'!I:I,MATCH("INN",'Dus-intors'!A:A,0))),"") | K13: =IF(OR(COUNT(F13:G13)=0,COUNT(H13:I13)=0),"",MIN(F13:G13)+MIN(H13:I13)+N(J13)) | L13: =IF(K13="","",IF(F13=MIN(F13:G13),"26.11","27.11")&" → "&IF(H13=MIN(H13:I13),"30.11","01.12"))
A14: BSL | B14: Basel/Mulhouse | C14: FKB | D14: Karlsruhe/Baden-Baden | E14: tren ~1h30 (Colmar/Strasbourg pe drum) | F14: =IFERROR(IF(INDEX('Dus-intors'!F:F,MATCH("BSL",'Dus-intors'!A:A,0))="","",INDEX('Dus-intors'!F:F,MATCH("BSL",'Dus-intors'!A:A,0))),"") | G14: =IFERROR(IF(INDEX('Dus-intors'!G:G,MATCH("BSL",'Dus-intors'!A:A,0))="","",INDEX('Dus-intors'!G:G,MATCH("BSL",'Dus-intors'!A:A,0))),"") | H14: =IFERROR(IF(INDEX('Dus-intors'!H:H,MATCH("FKB",'Dus-intors'!A:A,0))="","",INDEX('Dus-intors'!H:H,MATCH("FKB",'Dus-intors'!A:A,0))),"") | I14: =IFERROR(IF(INDEX('Dus-intors'!I:I,MATCH("FKB",'Dus-intors'!A:A,0))="","",INDEX('Dus-intors'!I:I,MATCH("FKB",'Dus-intors'!A:A,0))),"") | K14: =IF(OR(COUNT(F14:G14)=0,COUNT(H14:I14)=0),"",MIN(F14:G14)+MIN(H14:I14)+N(J14)) | L14: =IF(K14="","",IF(F14=MIN(F14:G14),"26.11","27.11")&" → "&IF(H14=MIN(H14:I14),"30.11","01.12"))
A15: FKB | B15: Karlsruhe/Baden-Baden | C15: BSL | D15: Basel/Mulhouse | E15: tren ~1h30 | F15: =IFERROR(IF(INDEX('Dus-intors'!F:F,MATCH("FKB",'Dus-intors'!A:A,0))="","",INDEX('Dus-intors'!F:F,MATCH("FKB",'Dus-intors'!A:A,0))),"") | G15: =IFERROR(IF(INDEX('Dus-intors'!G:G,MATCH("FKB",'Dus-intors'!A:A,0))="","",INDEX('Dus-intors'!G:G,MATCH("FKB",'Dus-intors'!A:A,0))),"") | H15: =IFERROR(IF(INDEX('Dus-intors'!H:H,MATCH("BSL",'Dus-intors'!A:A,0))="","",INDEX('Dus-intors'!H:H,MATCH("BSL",'Dus-intors'!A:A,0))),"") | I15: =IFERROR(IF(INDEX('Dus-intors'!I:I,MATCH("BSL",'Dus-intors'!A:A,0))="","",INDEX('Dus-intors'!I:I,MATCH("BSL",'Dus-intors'!A:A,0))),"") | K15: =IF(OR(COUNT(F15:G15)=0,COUNT(H15:I15)=0),"",MIN(F15:G15)+MIN(H15:I15)+N(J15)) | L15: =IF(K15="","",IF(F15=MIN(F15:G15),"26.11","27.11")&" → "&IF(H15=MIN(H15:I15),"30.11","01.12"))
A16: BSL | B16: Basel/Mulhouse | C16: SXB | D16: Strasbourg | E16: tren ~1h15 | F16: =IFERROR(IF(INDEX('Dus-intors'!F:F,MATCH("BSL",'Dus-intors'!A:A,0))="","",INDEX('Dus-intors'!F:F,MATCH("BSL",'Dus-intors'!A:A,0))),"") | G16: =IFERROR(IF(INDEX('Dus-intors'!G:G,MATCH("BSL",'Dus-intors'!A:A,0))="","",INDEX('Dus-intors'!G:G,MATCH("BSL",'Dus-intors'!A:A,0))),"") | H16: =IFERROR(IF(INDEX('Dus-intors'!H:H,MATCH("SXB",'Dus-intors'!A:A,0))="","",INDEX('Dus-intors'!H:H,MATCH("SXB",'Dus-intors'!A:A,0))),"") | I16: =IFERROR(IF(INDEX('Dus-intors'!I:I,MATCH("SXB",'Dus-intors'!A:A,0))="","",INDEX('Dus-intors'!I:I,MATCH("SXB",'Dus-intors'!A:A,0))),"") | K16: =IF(OR(COUNT(F16:G16)=0,COUNT(H16:I16)=0),"",MIN(F16:G16)+MIN(H16:I16)+N(J16)) | L16: =IF(K16="","",IF(F16=MIN(F16:G16),"26.11","27.11")&" → "&IF(H16=MIN(H16:I16),"30.11","01.12"))
A17: SXB | B17: Strasbourg | C17: BSL | D17: Basel/Mulhouse | E17: tren ~1h15 | F17: =IFERROR(IF(INDEX('Dus-intors'!F:F,MATCH("SXB",'Dus-intors'!A:A,0))="","",INDEX('Dus-intors'!F:F,MATCH("SXB",'Dus-intors'!A:A,0))),"") | G17: =IFERROR(IF(INDEX('Dus-intors'!G:G,MATCH("SXB",'Dus-intors'!A:A,0))="","",INDEX('Dus-intors'!G:G,MATCH("SXB",'Dus-intors'!A:A,0))),"") | H17: =IFERROR(IF(INDEX('Dus-intors'!H:H,MATCH("BSL",'Dus-intors'!A:A,0))="","",INDEX('Dus-intors'!H:H,MATCH("BSL",'Dus-intors'!A:A,0))),"") | I17: =IFERROR(IF(INDEX('Dus-intors'!I:I,MATCH("BSL",'Dus-intors'!A:A,0))="","",INDEX('Dus-intors'!I:I,MATCH("BSL",'Dus-intors'!A:A,0))),"") | K17: =IF(OR(COUNT(F17:G17)=0,COUNT(H17:I17)=0),"",MIN(F17:G17)+MIN(H17:I17)+N(J17)) | L17: =IF(K17="","",IF(F17=MIN(F17:G17),"26.11","27.11")&" → "&IF(H17=MIN(H17:I17),"30.11","01.12"))
A18: BSL | B18: Basel/Mulhouse | C18: ZRH | D18: Zürich | E18: tren ~1h | F18: =IFERROR(IF(INDEX('Dus-intors'!F:F,MATCH("BSL",'Dus-intors'!A:A,0))="","",INDEX('Dus-intors'!F:F,MATCH("BSL",'Dus-intors'!A:A,0))),"") | G18: =IFERROR(IF(INDEX('Dus-intors'!G:G,MATCH("BSL",'Dus-intors'!A:A,0))="","",INDEX('Dus-intors'!G:G,MATCH("BSL",'Dus-intors'!A:A,0))),"") | H18: =IFERROR(IF(INDEX('Dus-intors'!H:H,MATCH("ZRH",'Dus-intors'!A:A,0))="","",INDEX('Dus-intors'!H:H,MATCH("ZRH",'Dus-intors'!A:A,0))),"") | I18: =IFERROR(IF(INDEX('Dus-intors'!I:I,MATCH("ZRH",'Dus-intors'!A:A,0))="","",INDEX('Dus-intors'!I:I,MATCH("ZRH",'Dus-intors'!A:A,0))),"") | K18: =IF(OR(COUNT(F18:G18)=0,COUNT(H18:I18)=0),"",MIN(F18:G18)+MIN(H18:I18)+N(J18)) | L18: =IF(K18="","",IF(F18=MIN(F18:G18),"26.11","27.11")&" → "&IF(H18=MIN(H18:I18),"30.11","01.12"))
A19: ZRH | B19: Zürich | C19: BSL | D19: Basel/Mulhouse | E19: tren ~1h | F19: =IFERROR(IF(INDEX('Dus-intors'!F:F,MATCH("ZRH",'Dus-intors'!A:A,0))="","",INDEX('Dus-intors'!F:F,MATCH("ZRH",'Dus-intors'!A:A,0))),"") | G19: =IFERROR(IF(INDEX('Dus-intors'!G:G,MATCH("ZRH",'Dus-intors'!A:A,0))="","",INDEX('Dus-intors'!G:G,MATCH("ZRH",'Dus-intors'!A:A,0))),"") | H19: =IFERROR(IF(INDEX('Dus-intors'!H:H,MATCH("BSL",'Dus-intors'!A:A,0))="","",INDEX('Dus-intors'!H:H,MATCH("BSL",'Dus-intors'!A:A,0))),"") | I19: =IFERROR(IF(INDEX('Dus-intors'!I:I,MATCH("BSL",'Dus-intors'!A:A,0))="","",INDEX('Dus-intors'!I:I,MATCH("BSL",'Dus-intors'!A:A,0))),"") | K19: =IF(OR(COUNT(F19:G19)=0,COUNT(H19:I19)=0),"",MIN(F19:G19)+MIN(H19:I19)+N(J19)) | L19: =IF(K19="","",IF(F19=MIN(F19:G19),"26.11","27.11")&" → "&IF(H19=MIN(H19:I19),"30.11","01.12"))
A20: FKB | B20: Karlsruhe/Baden-Baden | C20: HHN | D20: Frankfurt Hahn | E20: autocar/tren ~2h | F20: =IFERROR(IF(INDEX('Dus-intors'!F:F,MATCH("FKB",'Dus-intors'!A:A,0))="","",INDEX('Dus-intors'!F:F,MATCH("FKB",'Dus-intors'!A:A,0))),"") | G20: =IFERROR(IF(INDEX('Dus-intors'!G:G,MATCH("FKB",'Dus-intors'!A:A,0))="","",INDEX('Dus-intors'!G:G,MATCH("FKB",'Dus-intors'!A:A,0))),"") | H20: =IFERROR(IF(INDEX('Dus-intors'!H:H,MATCH("HHN",'Dus-intors'!A:A,0))="","",INDEX('Dus-intors'!H:H,MATCH("HHN",'Dus-intors'!A:A,0))),"") | I20: =IFERROR(IF(INDEX('Dus-intors'!I:I,MATCH("HHN",'Dus-intors'!A:A,0))="","",INDEX('Dus-intors'!I:I,MATCH("HHN",'Dus-intors'!A:A,0))),"") | K20: =IF(OR(COUNT(F20:G20)=0,COUNT(H20:I20)=0),"",MIN(F20:G20)+MIN(H20:I20)+N(J20)) | L20: =IF(K20="","",IF(F20=MIN(F20:G20),"26.11","27.11")&" → "&IF(H20=MIN(H20:I20),"30.11","01.12"))
A21: HHN | B21: Frankfurt Hahn | C21: FKB | D21: Karlsruhe/Baden-Baden | E21: autocar/tren ~2h | F21: =IFERROR(IF(INDEX('Dus-intors'!F:F,MATCH("HHN",'Dus-intors'!A:A,0))="","",INDEX('Dus-intors'!F:F,MATCH("HHN",'Dus-intors'!A:A,0))),"") | G21: =IFERROR(IF(INDEX('Dus-intors'!G:G,MATCH("HHN",'Dus-intors'!A:A,0))="","",INDEX('Dus-intors'!G:G,MATCH("HHN",'Dus-intors'!A:A,0))),"") | H21: =IFERROR(IF(INDEX('Dus-intors'!H:H,MATCH("FKB",'Dus-intors'!A:A,0))="","",INDEX('Dus-intors'!H:H,MATCH("FKB",'Dus-intors'!A:A,0))),"") | I21: =IFERROR(IF(INDEX('Dus-intors'!I:I,MATCH("FKB",'Dus-intors'!A:A,0))="","",INDEX('Dus-intors'!I:I,MATCH("FKB",'Dus-intors'!A:A,0))),"") | K21: =IF(OR(COUNT(F21:G21)=0,COUNT(H21:I21)=0),"",MIN(F21:G21)+MIN(H21:I21)+N(J21)) | L21: =IF(K21="","",IF(F21=MIN(F21:G21),"26.11","27.11")&" → "&IF(H21=MIN(H21:I21),"30.11","01.12"))
A22: FRA | B22: Frankfurt | C22: FKB | D22: Karlsruhe/Baden-Baden | E22: tren ~1h | F22: =IFERROR(IF(INDEX('Dus-intors'!F:F,MATCH("FRA",'Dus-intors'!A:A,0))="","",INDEX('Dus-intors'!F:F,MATCH("FRA",'Dus-intors'!A:A,0))),"") | G22: =IFERROR(IF(INDEX('Dus-intors'!G:G,MATCH("FRA",'Dus-intors'!A:A,0))="","",INDEX('Dus-intors'!G:G,MATCH("FRA",'Dus-intors'!A:A,0))),"") | H22: =IFERROR(IF(INDEX('Dus-intors'!H:H,MATCH("FKB",'Dus-intors'!A:A,0))="","",INDEX('Dus-intors'!H:H,MATCH("FKB",'Dus-intors'!A:A,0))),"") | I22: =IFERROR(IF(INDEX('Dus-intors'!I:I,MATCH("FKB",'Dus-intors'!A:A,0))="","",INDEX('Dus-intors'!I:I,MATCH("FKB",'Dus-intors'!A:A,0))),"") | K22: =IF(OR(COUNT(F22:G22)=0,COUNT(H22:I22)=0),"",MIN(F22:G22)+MIN(H22:I22)+N(J22)) | L22: =IF(K22="","",IF(F22=MIN(F22:G22),"26.11","27.11")&" → "&IF(H22=MIN(H22:I22),"30.11","01.12"))
A23: CGN | B23: Köln | C23: DTM | D23: Dortmund | E23: tren ~1h20 | F23: =IFERROR(IF(INDEX('Dus-intors'!F:F,MATCH("CGN",'Dus-intors'!A:A,0))="","",INDEX('Dus-intors'!F:F,MATCH("CGN",'Dus-intors'!A:A,0))),"") | G23: =IFERROR(IF(INDEX('Dus-intors'!G:G,MATCH("CGN",'Dus-intors'!A:A,0))="","",INDEX('Dus-intors'!G:G,MATCH("CGN",'Dus-intors'!A:A,0))),"") | H23: =IFERROR(IF(INDEX('Dus-intors'!H:H,MATCH("DTM",'Dus-intors'!A:A,0))="","",INDEX('Dus-intors'!H:H,MATCH("DTM",'Dus-intors'!A:A,0))),"") | I23: =IFERROR(IF(INDEX('Dus-intors'!I:I,MATCH("DTM",'Dus-intors'!A:A,0))="","",INDEX('Dus-intors'!I:I,MATCH("DTM",'Dus-intors'!A:A,0))),"") | K23: =IF(OR(COUNT(F23:G23)=0,COUNT(H23:I23)=0),"",MIN(F23:G23)+MIN(H23:I23)+N(J23)) | L23: =IF(K23="","",IF(F23=MIN(F23:G23),"26.11","27.11")&" → "&IF(H23=MIN(H23:I23),"30.11","01.12"))
A24: DTM | B24: Dortmund | C24: CGN | D24: Köln | E24: tren ~1h20 | F24: =IFERROR(IF(INDEX('Dus-intors'!F:F,MATCH("DTM",'Dus-intors'!A:A,0))="","",INDEX('Dus-intors'!F:F,MATCH("DTM",'Dus-intors'!A:A,0))),"") | G24: =IFERROR(IF(INDEX('Dus-intors'!G:G,MATCH("DTM",'Dus-intors'!A:A,0))="","",INDEX('Dus-intors'!G:G,MATCH("DTM",'Dus-intors'!A:A,0))),"") | H24: =IFERROR(IF(INDEX('Dus-intors'!H:H,MATCH("CGN",'Dus-intors'!A:A,0))="","",INDEX('Dus-intors'!H:H,MATCH("CGN",'Dus-intors'!A:A,0))),"") | I24: =IFERROR(IF(INDEX('Dus-intors'!I:I,MATCH("CGN",'Dus-intors'!A:A,0))="","",INDEX('Dus-intors'!I:I,MATCH("CGN",'Dus-intors'!A:A,0))),"") | K24: =IF(OR(COUNT(F24:G24)=0,COUNT(H24:I24)=0),"",MIN(F24:G24)+MIN(H24:I24)+N(J24)) | L24: =IF(K24="","",IF(F24=MIN(F24:G24),"26.11","27.11")&" → "&IF(H24=MIN(H24:I24),"30.11","01.12"))
A25: CGN | B25: Köln | C25: MST | D25: Maastricht/Aachen | E25: tren ~1h30 via Aachen | F25: =IFERROR(IF(INDEX('Dus-intors'!F:F,MATCH("CGN",'Dus-intors'!A:A,0))="","",INDEX('Dus-intors'!F:F,MATCH("CGN",'Dus-intors'!A:A,0))),"") | G25: =IFERROR(IF(INDEX('Dus-intors'!G:G,MATCH("CGN",'Dus-intors'!A:A,0))="","",INDEX('Dus-intors'!G:G,MATCH("CGN",'Dus-intors'!A:A,0))),"") | H25: =IFERROR(IF(INDEX('Dus-intors'!H:H,MATCH("MST",'Dus-intors'!A:A,0))="","",INDEX('Dus-intors'!H:H,MATCH("MST",'Dus-intors'!A:A,0))),"") | I25: =IFERROR(IF(INDEX('Dus-intors'!I:I,MATCH("MST",'Dus-intors'!A:A,0))="","",INDEX('Dus-intors'!I:I,MATCH("MST",'Dus-intors'!A:A,0))),"") | K25: =IF(OR(COUNT(F25:G25)=0,COUNT(H25:I25)=0),"",MIN(F25:G25)+MIN(H25:I25)+N(J25)) | L25: =IF(K25="","",IF(F25=MIN(F25:G25),"26.11","27.11")&" → "&IF(H25=MIN(H25:I25),"30.11","01.12"))
A26: MST | B26: Maastricht/Aachen | C26: CGN | D26: Köln | E26: tren ~1h30 | F26: =IFERROR(IF(INDEX('Dus-intors'!F:F,MATCH("MST",'Dus-intors'!A:A,0))="","",INDEX('Dus-intors'!F:F,MATCH("MST",'Dus-intors'!A:A,0))),"") | G26: =IFERROR(IF(INDEX('Dus-intors'!G:G,MATCH("MST",'Dus-intors'!A:A,0))="","",INDEX('Dus-intors'!G:G,MATCH("MST",'Dus-intors'!A:A,0))),"") | H26: =IFERROR(IF(INDEX('Dus-intors'!H:H,MATCH("CGN",'Dus-intors'!A:A,0))="","",INDEX('Dus-intors'!H:H,MATCH("CGN",'Dus-intors'!A:A,0))),"") | I26: =IFERROR(IF(INDEX('Dus-intors'!I:I,MATCH("CGN",'Dus-intors'!A:A,0))="","",INDEX('Dus-intors'!I:I,MATCH("CGN",'Dus-intors'!A:A,0))),"") | K26: =IF(OR(COUNT(F26:G26)=0,COUNT(H26:I26)=0),"",MIN(F26:G26)+MIN(H26:I26)+N(J26)) | L26: =IF(K26="","",IF(F26=MIN(F26:G26),"26.11","27.11")&" → "&IF(H26=MIN(H26:I26),"30.11","01.12"))
A27: CRL | B27: Bruxelles Charleroi | C27: MST | D27: Maastricht/Aachen | E27: tren ~2h | F27: =IFERROR(IF(INDEX('Dus-intors'!F:F,MATCH("CRL",'Dus-intors'!A:A,0))="","",INDEX('Dus-intors'!F:F,MATCH("CRL",'Dus-intors'!A:A,0))),"") | G27: =IFERROR(IF(INDEX('Dus-intors'!G:G,MATCH("CRL",'Dus-intors'!A:A,0))="","",INDEX('Dus-intors'!G:G,MATCH("CRL",'Dus-intors'!A:A,0))),"") | H27: =IFERROR(IF(INDEX('Dus-intors'!H:H,MATCH("MST",'Dus-intors'!A:A,0))="","",INDEX('Dus-intors'!H:H,MATCH("MST",'Dus-intors'!A:A,0))),"") | I27: =IFERROR(IF(INDEX('Dus-intors'!I:I,MATCH("MST",'Dus-intors'!A:A,0))="","",INDEX('Dus-intors'!I:I,MATCH("MST",'Dus-intors'!A:A,0))),"") | K27: =IF(OR(COUNT(F27:G27)=0,COUNT(H27:I27)=0),"",MIN(F27:G27)+MIN(H27:I27)+N(J27)) | L27: =IF(K27="","",IF(F27=MIN(F27:G27),"26.11","27.11")&" → "&IF(H27=MIN(H27:I27),"30.11","01.12"))
A28: EIN | B28: Eindhoven | C28: CGN | D28: Köln | E28: tren ~2h | F28: =IFERROR(IF(INDEX('Dus-intors'!F:F,MATCH("EIN",'Dus-intors'!A:A,0))="","",INDEX('Dus-intors'!F:F,MATCH("EIN",'Dus-intors'!A:A,0))),"") | G28: =IFERROR(IF(INDEX('Dus-intors'!G:G,MATCH("EIN",'Dus-intors'!A:A,0))="","",INDEX('Dus-intors'!G:G,MATCH("EIN",'Dus-intors'!A:A,0))),"") | H28: =IFERROR(IF(INDEX('Dus-intors'!H:H,MATCH("CGN",'Dus-intors'!A:A,0))="","",INDEX('Dus-intors'!H:H,MATCH("CGN",'Dus-intors'!A:A,0))),"") | I28: =IFERROR(IF(INDEX('Dus-intors'!I:I,MATCH("CGN",'Dus-intors'!A:A,0))="","",INDEX('Dus-intors'!I:I,MATCH("CGN",'Dus-intors'!A:A,0))),"") | K28: =IF(OR(COUNT(F28:G28)=0,COUNT(H28:I28)=0),"",MIN(F28:G28)+MIN(H28:I28)+N(J28)) | L28: =IF(K28="","",IF(F28=MIN(F28:G28),"26.11","27.11")&" → "&IF(H28=MIN(H28:I28),"30.11","01.12"))
A29: CRL | B29: Bruxelles Charleroi | C29: EIN | D29: Eindhoven | E29: tren ~2h | F29: =IFERROR(IF(INDEX('Dus-intors'!F:F,MATCH("CRL",'Dus-intors'!A:A,0))="","",INDEX('Dus-intors'!F:F,MATCH("CRL",'Dus-intors'!A:A,0))),"") | G29: =IFERROR(IF(INDEX('Dus-intors'!G:G,MATCH("CRL",'Dus-intors'!A:A,0))="","",INDEX('Dus-intors'!G:G,MATCH("CRL",'Dus-intors'!A:A,0))),"") | H29: =IFERROR(IF(INDEX('Dus-intors'!H:H,MATCH("EIN",'Dus-intors'!A:A,0))="","",INDEX('Dus-intors'!H:H,MATCH("EIN",'Dus-intors'!A:A,0))),"") | I29: =IFERROR(IF(INDEX('Dus-intors'!I:I,MATCH("EIN",'Dus-intors'!A:A,0))="","",INDEX('Dus-intors'!I:I,MATCH("EIN",'Dus-intors'!A:A,0))),"") | K29: =IF(OR(COUNT(F29:G29)=0,COUNT(H29:I29)=0),"",MIN(F29:G29)+MIN(H29:I29)+N(J29)) | L29: =IF(K29="","",IF(F29=MIN(F29:G29),"26.11","27.11")&" → "&IF(H29=MIN(H29:I29),"30.11","01.12"))
A30: CRL | B30: Bruxelles Charleroi | C30: BVA | D30: Paris Beauvais | E30: tren/autocar ~4h via Paris | F30: =IFERROR(IF(INDEX('Dus-intors'!F:F,MATCH("CRL",'Dus-intors'!A:A,0))="","",INDEX('Dus-intors'!F:F,MATCH("CRL",'Dus-intors'!A:A,0))),"") | G30: =IFERROR(IF(INDEX('Dus-intors'!G:G,MATCH("CRL",'Dus-intors'!A:A,0))="","",INDEX('Dus-intors'!G:G,MATCH("CRL",'Dus-intors'!A:A,0))),"") | H30: =IFERROR(IF(INDEX('Dus-intors'!H:H,MATCH("BVA",'Dus-intors'!A:A,0))="","",INDEX('Dus-intors'!H:H,MATCH("BVA",'Dus-intors'!A:A,0))),"") | I30: =IFERROR(IF(INDEX('Dus-intors'!I:I,MATCH("BVA",'Dus-intors'!A:A,0))="","",INDEX('Dus-intors'!I:I,MATCH("BVA",'Dus-intors'!A:A,0))),"") | K30: =IF(OR(COUNT(F30:G30)=0,COUNT(H30:I30)=0),"",MIN(F30:G30)+MIN(H30:I30)+N(J30)) | L30: =IF(K30="","",IF(F30=MIN(F30:G30),"26.11","27.11")&" → "&IF(H30=MIN(H30:I30),"30.11","01.12"))
A31: NUE | B31: Nürnberg | C31: PRG | D31: Praga | E31: autobuz ~3h45 | F31: =IFERROR(IF(INDEX('Dus-intors'!F:F,MATCH("NUE",'Dus-intors'!A:A,0))="","",INDEX('Dus-intors'!F:F,MATCH("NUE",'Dus-intors'!A:A,0))),"") | G31: =IFERROR(IF(INDEX('Dus-intors'!G:G,MATCH("NUE",'Dus-intors'!A:A,0))="","",INDEX('Dus-intors'!G:G,MATCH("NUE",'Dus-intors'!A:A,0))),"") | H31: =IFERROR(IF(INDEX('Dus-intors'!H:H,MATCH("PRG",'Dus-intors'!A:A,0))="","",INDEX('Dus-intors'!H:H,MATCH("PRG",'Dus-intors'!A:A,0))),"") | I31: =IFERROR(IF(INDEX('Dus-intors'!I:I,MATCH("PRG",'Dus-intors'!A:A,0))="","",INDEX('Dus-intors'!I:I,MATCH("PRG",'Dus-intors'!A:A,0))),"") | K31: =IF(OR(COUNT(F31:G31)=0,COUNT(H31:I31)=0),"",MIN(F31:G31)+MIN(H31:I31)+N(J31)) | L31: =IF(K31="","",IF(F31=MIN(F31:G31),"26.11","27.11")&" → "&IF(H31=MIN(H31:I31),"30.11","01.12"))
A32: PRG | B32: Praga | C32: NUE | D32: Nürnberg | E32: autobuz ~3h45 | F32: =IFERROR(IF(INDEX('Dus-intors'!F:F,MATCH("PRG",'Dus-intors'!A:A,0))="","",INDEX('Dus-intors'!F:F,MATCH("PRG",'Dus-intors'!A:A,0))),"") | G32: =IFERROR(IF(INDEX('Dus-intors'!G:G,MATCH("PRG",'Dus-intors'!A:A,0))="","",INDEX('Dus-intors'!G:G,MATCH("PRG",'Dus-intors'!A:A,0))),"") | H32: =IFERROR(IF(INDEX('Dus-intors'!H:H,MATCH("NUE",'Dus-intors'!A:A,0))="","",INDEX('Dus-intors'!H:H,MATCH("NUE",'Dus-intors'!A:A,0))),"") | I32: =IFERROR(IF(INDEX('Dus-intors'!I:I,MATCH("NUE",'Dus-intors'!A:A,0))="","",INDEX('Dus-intors'!I:I,MATCH("NUE",'Dus-intors'!A:A,0))),"") | K32: =IF(OR(COUNT(F32:G32)=0,COUNT(H32:I32)=0),"",MIN(F32:G32)+MIN(H32:I32)+N(J32)) | L32: =IF(K32="","",IF(F32=MIN(F32:G32),"26.11","27.11")&" → "&IF(H32=MIN(H32:I32),"30.11","01.12"))
A33: VIE | B33: Viena | C33: BTS | D33: Bratislava | E33: autobuz/tren ~1h | F33: =IFERROR(IF(INDEX('Dus-intors'!F:F,MATCH("VIE",'Dus-intors'!A:A,0))="","",INDEX('Dus-intors'!F:F,MATCH("VIE",'Dus-intors'!A:A,0))),"") | G33: =IFERROR(IF(INDEX('Dus-intors'!G:G,MATCH("VIE",'Dus-intors'!A:A,0))="","",INDEX('Dus-intors'!G:G,MATCH("VIE",'Dus-intors'!A:A,0))),"") | H33: =IFERROR(IF(INDEX('Dus-intors'!H:H,MATCH("BTS",'Dus-intors'!A:A,0))="","",INDEX('Dus-intors'!H:H,MATCH("BTS",'Dus-intors'!A:A,0))),"") | I33: =IFERROR(IF(INDEX('Dus-intors'!I:I,MATCH("BTS",'Dus-intors'!A:A,0))="","",INDEX('Dus-intors'!I:I,MATCH("BTS",'Dus-intors'!A:A,0))),"") | K33: =IF(OR(COUNT(F33:G33)=0,COUNT(H33:I33)=0),"",MIN(F33:G33)+MIN(H33:I33)+N(J33)) | L33: =IF(K33="","",IF(F33=MIN(F33:G33),"26.11","27.11")&" → "&IF(H33=MIN(H33:I33),"30.11","01.12"))
A34: BTS | B34: Bratislava | C34: VIE | D34: Viena | E34: autobuz/tren ~1h | F34: =IFERROR(IF(INDEX('Dus-intors'!F:F,MATCH("BTS",'Dus-intors'!A:A,0))="","",INDEX('Dus-intors'!F:F,MATCH("BTS",'Dus-intors'!A:A,0))),"") | G34: =IFERROR(IF(INDEX('Dus-intors'!G:G,MATCH("BTS",'Dus-intors'!A:A,0))="","",INDEX('Dus-intors'!G:G,MATCH("BTS",'Dus-intors'!A:A,0))),"") | H34: =IFERROR(IF(INDEX('Dus-intors'!H:H,MATCH("VIE",'Dus-intors'!A:A,0))="","",INDEX('Dus-intors'!H:H,MATCH("VIE",'Dus-intors'!A:A,0))),"") | I34: =IFERROR(IF(INDEX('Dus-intors'!I:I,MATCH("VIE",'Dus-intors'!A:A,0))="","",INDEX('Dus-intors'!I:I,MATCH("VIE",'Dus-intors'!A:A,0))),"") | K34: =IF(OR(COUNT(F34:G34)=0,COUNT(H34:I34)=0),"",MIN(F34:G34)+MIN(H34:I34)+N(J34)) | L34: =IF(K34="","",IF(F34=MIN(F34:G34),"26.11","27.11")&" → "&IF(H34=MIN(H34:I34),"30.11","01.12"))
A35: VIE | B35: Viena | C35: SZG | D35: Salzburg | E35: tren ~2h30 | F35: =IFERROR(IF(INDEX('Dus-intors'!F:F,MATCH("VIE",'Dus-intors'!A:A,0))="","",INDEX('Dus-intors'!F:F,MATCH("VIE",'Dus-intors'!A:A,0))),"") | G35: =IFERROR(IF(INDEX('Dus-intors'!G:G,MATCH("VIE",'Dus-intors'!A:A,0))="","",INDEX('Dus-intors'!G:G,MATCH("VIE",'Dus-intors'!A:A,0))),"") | H35: =IFERROR(IF(INDEX('Dus-intors'!H:H,MATCH("SZG",'Dus-intors'!A:A,0))="","",INDEX('Dus-intors'!H:H,MATCH("SZG",'Dus-intors'!A:A,0))),"") | I35: =IFERROR(IF(INDEX('Dus-intors'!I:I,MATCH("SZG",'Dus-intors'!A:A,0))="","",INDEX('Dus-intors'!I:I,MATCH("SZG",'Dus-intors'!A:A,0))),"") | K35: =IF(OR(COUNT(F35:G35)=0,COUNT(H35:I35)=0),"",MIN(F35:G35)+MIN(H35:I35)+N(J35)) | L35: =IF(K35="","",IF(F35=MIN(F35:G35),"26.11","27.11")&" → "&IF(H35=MIN(H35:I35),"30.11","01.12"))
A36: SZG | B36: Salzburg | C36: VIE | D36: Viena | E36: tren ~2h30 | F36: =IFERROR(IF(INDEX('Dus-intors'!F:F,MATCH("SZG",'Dus-intors'!A:A,0))="","",INDEX('Dus-intors'!F:F,MATCH("SZG",'Dus-intors'!A:A,0))),"") | G36: =IFERROR(IF(INDEX('Dus-intors'!G:G,MATCH("SZG",'Dus-intors'!A:A,0))="","",INDEX('Dus-intors'!G:G,MATCH("SZG",'Dus-intors'!A:A,0))),"") | H36: =IFERROR(IF(INDEX('Dus-intors'!H:H,MATCH("VIE",'Dus-intors'!A:A,0))="","",INDEX('Dus-intors'!H:H,MATCH("VIE",'Dus-intors'!A:A,0))),"") | I36: =IFERROR(IF(INDEX('Dus-intors'!I:I,MATCH("VIE",'Dus-intors'!A:A,0))="","",INDEX('Dus-intors'!I:I,MATCH("VIE",'Dus-intors'!A:A,0))),"") | K36: =IF(OR(COUNT(F36:G36)=0,COUNT(H36:I36)=0),"",MIN(F36:G36)+MIN(H36:I36)+N(J36)) | L36: =IF(K36="","",IF(F36=MIN(F36:G36),"26.11","27.11")&" → "&IF(H36=MIN(H36:I36),"30.11","01.12"))
A37: SZG | B37: Salzburg | C37: MUC | D37: München | E37: tren ~1h30 | F37: =IFERROR(IF(INDEX('Dus-intors'!F:F,MATCH("SZG",'Dus-intors'!A:A,0))="","",INDEX('Dus-intors'!F:F,MATCH("SZG",'Dus-intors'!A:A,0))),"") | G37: =IFERROR(IF(INDEX('Dus-intors'!G:G,MATCH("SZG",'Dus-intors'!A:A,0))="","",INDEX('Dus-intors'!G:G,MATCH("SZG",'Dus-intors'!A:A,0))),"") | H37: =IFERROR(IF(INDEX('Dus-intors'!H:H,MATCH("MUC",'Dus-intors'!A:A,0))="","",INDEX('Dus-intors'!H:H,MATCH("MUC",'Dus-intors'!A:A,0))),"") | I37: =IFERROR(IF(INDEX('Dus-intors'!I:I,MATCH("MUC",'Dus-intors'!A:A,0))="","",INDEX('Dus-intors'!I:I,MATCH("MUC",'Dus-intors'!A:A,0))),"") | K37: =IF(OR(COUNT(F37:G37)=0,COUNT(H37:I37)=0),"",MIN(F37:G37)+MIN(H37:I37)+N(J37)) | L37: =IF(K37="","",IF(F37=MIN(F37:G37),"26.11","27.11")&" → "&IF(H37=MIN(H37:I37),"30.11","01.12"))
A38: MUC | B38: München | C38: SZG | D38: Salzburg | E38: tren ~1h30 | F38: =IFERROR(IF(INDEX('Dus-intors'!F:F,MATCH("MUC",'Dus-intors'!A:A,0))="","",INDEX('Dus-intors'!F:F,MATCH("MUC",'Dus-intors'!A:A,0))),"") | G38: =IFERROR(IF(INDEX('Dus-intors'!G:G,MATCH("MUC",'Dus-intors'!A:A,0))="","",INDEX('Dus-intors'!G:G,MATCH("MUC",'Dus-intors'!A:A,0))),"") | H38: =IFERROR(IF(INDEX('Dus-intors'!H:H,MATCH("SZG",'Dus-intors'!A:A,0))="","",INDEX('Dus-intors'!H:H,MATCH("SZG",'Dus-intors'!A:A,0))),"") | I38: =IFERROR(IF(INDEX('Dus-intors'!I:I,MATCH("SZG",'Dus-intors'!A:A,0))="","",INDEX('Dus-intors'!I:I,MATCH("SZG",'Dus-intors'!A:A,0))),"") | K38: =IF(OR(COUNT(F38:G38)=0,COUNT(H38:I38)=0),"",MIN(F38:G38)+MIN(H38:I38)+N(J38)) | L38: =IF(K38="","",IF(F38=MIN(F38:G38),"26.11","27.11")&" → "&IF(H38=MIN(H38:I38),"30.11","01.12"))
A39: BGY | B39: Milano Bergamo | C39: TSF | D39: Treviso (Veneția) | E39: tren ~2h30 via Verona | F39: =IFERROR(IF(INDEX('Dus-intors'!F:F,MATCH("BGY",'Dus-intors'!A:A,0))="","",INDEX('Dus-intors'!F:F,MATCH("BGY",'Dus-intors'!A:A,0))),"") | G39: =IFERROR(IF(INDEX('Dus-intors'!G:G,MATCH("BGY",'Dus-intors'!A:A,0))="","",INDEX('Dus-intors'!G:G,MATCH("BGY",'Dus-intors'!A:A,0))),"") | H39: =IFERROR(IF(INDEX('Dus-intors'!H:H,MATCH("TSF",'Dus-intors'!A:A,0))="","",INDEX('Dus-intors'!H:H,MATCH("TSF",'Dus-intors'!A:A,0))),"") | I39: =IFERROR(IF(INDEX('Dus-intors'!I:I,MATCH("TSF",'Dus-intors'!A:A,0))="","",INDEX('Dus-intors'!I:I,MATCH("TSF",'Dus-intors'!A:A,0))),"") | K39: =IF(OR(COUNT(F39:G39)=0,COUNT(H39:I39)=0),"",MIN(F39:G39)+MIN(H39:I39)+N(J39)) | L39: =IF(K39="","",IF(F39=MIN(F39:G39),"26.11","27.11")&" → "&IF(H39=MIN(H39:I39),"30.11","01.12"))
A40: TSF | B40: Treviso (Veneția) | C40: BGY | D40: Milano Bergamo | E40: tren ~2h30 | F40: =IFERROR(IF(INDEX('Dus-intors'!F:F,MATCH("TSF",'Dus-intors'!A:A,0))="","",INDEX('Dus-intors'!F:F,MATCH("TSF",'Dus-intors'!A:A,0))),"") | G40: =IFERROR(IF(INDEX('Dus-intors'!G:G,MATCH("TSF",'Dus-intors'!A:A,0))="","",INDEX('Dus-intors'!G:G,MATCH("TSF",'Dus-intors'!A:A,0))),"") | H40: =IFERROR(IF(INDEX('Dus-intors'!H:H,MATCH("BGY",'Dus-intors'!A:A,0))="","",INDEX('Dus-intors'!H:H,MATCH("BGY",'Dus-intors'!A:A,0))),"") | I40: =IFERROR(IF(INDEX('Dus-intors'!I:I,MATCH("BGY",'Dus-intors'!A:A,0))="","",INDEX('Dus-intors'!I:I,MATCH("BGY",'Dus-intors'!A:A,0))),"") | K40: =IF(OR(COUNT(F40:G40)=0,COUNT(H40:I40)=0),"",MIN(F40:G40)+MIN(H40:I40)+N(J40)) | L40: =IF(K40="","",IF(F40=MIN(F40:G40),"26.11","27.11")&" → "&IF(H40=MIN(H40:I40),"30.11","01.12"))
...

Sheet Top 10
A1: Cele mai ieftine 10 variante dus-întors (se actualizează singur)
A3: Loc | B3: Destinație | C3: Total minim (RON) | D3: Zile
A4: 1 | B4: =IF(C4="","",INDEX('Dus-intors'!B$4:B$39,MATCH(C4,'Dus-intors'!L$4:L$39,0))) | C4: =IFERROR(SMALL('Dus-intors'!L$4:L$39,1),"") | D4: =IF(C4="","",INDEX('Dus-intors'!M$4:M$39,MATCH(C4,'Dus-intors'!L$4:L$39,0)))
A5: 2 | B5: =IF(C5="","",INDEX('Dus-intors'!B$4:B$39,MATCH(C5,'Dus-intors'!L$4:L$39,0))) | C5: =IFERROR(SMALL('Dus-intors'!L$4:L$39,2),"") | D5: =IF(C5="","",INDEX('Dus-intors'!M$4:M$39,MATCH(C5,'Dus-intors'!L$4:L$39,0)))
A6: 3 | B6: =IF(C6="","",INDEX('Dus-intors'!B$4:B$39,MATCH(C6,'Dus-intors'!L$4:L$39,0))) | C6: =IFERROR(SMALL('Dus-intors'!L$4:L$39,3),"") | D6: =IF(C6="","",INDEX('Dus-intors'!M$4:M$39,MATCH(C6,'Dus-intors'!L$4:L$39,0)))
A7: 4 | B7: =IF(C7="","",INDEX('Dus-intors'!B$4:B$39,MATCH(C7,'Dus-intors'!L$4:L$39,0))) | C7: =IFERROR(SMALL('Dus-intors'!L$4:L$39,4),"") | D7: =IF(C7="","",INDEX('Dus-intors'!M$4:M$39,MATCH(C7,'Dus-intors'!L$4:L$39,0)))
A8: 5 | B8: =IF(C8="","",INDEX('Dus-intors'!B$4:B$39,MATCH(C8,'Dus-intors'!L$4:L$39,0))) | C8: =IFERROR(SMALL('Dus-intors'!L$4:L$39,5),"") | D8: =IF(C8="","",INDEX('Dus-intors'!M$4:M$39,MATCH(C8,'Dus-intors'!L$4:L$39,0)))
A9: 6 | B9: =IF(C9="","",INDEX('Dus-intors'!B$4:B$39,MATCH(C9,'Dus-intors'!L$4:L$39,0))) | C9: =IFERROR(SMALL('Dus-intors'!L$4:L$39,6),"") | D9: =IF(C9="","",INDEX('Dus-intors'!M$4:M$39,MATCH(C9,'Dus-intors'!L$4:L$39,0)))
A10: 7 | B10: =IF(C10="","",INDEX('Dus-intors'!B$4:B$39,MATCH(C10,'Dus-intors'!L$4:L$39,0))) | C10: =IFERROR(SMALL('Dus-intors'!L$4:L$39,7),"") | D10: =IF(C10="","",INDEX('Dus-intors'!M$4:M$39,MATCH(C10,'Dus-intors'!L$4:L$39,0)))
A11: 8 | B11: =IF(C11="","",INDEX('Dus-intors'!B$4:B$39,MATCH(C11,'Dus-intors'!L$4:L$39,0))) | C11: =IFERROR(SMALL('Dus-intors'!L$4:L$39,8),"") | D11: =IF(C11="","",INDEX('Dus-intors'!M$4:M$39,MATCH(C11,'Dus-intors'!L$4:L$39,0)))
A12: 9 | B12: =IF(C12="","",INDEX('Dus-intors'!B$4:B$39,MATCH(C12,'Dus-intors'!L$4:L$39,0))) | C12: =IFERROR(SMALL('Dus-intors'!L$4:L$39,9),"") | D12: =IF(C12="","",INDEX('Dus-intors'!M$4:M$39,MATCH(C12,'Dus-intors'!L$4:L$39,0)))
A13: 10 | B13: =IF(C13="","",INDEX('Dus-intors'!B$4:B$39,MATCH(C13,'Dus-intors'!L$4:L$39,0))) | C13: =IFERROR(SMALL('Dus-intors'!L$4:L$39,10),"") | D13: =IF(C13="","",INDEX('Dus-intors'!M$4:M$39,MATCH(C13,'Dus-intors'!L$4:L$39,0)))

Sheet Sfaturi
A1: Sfaturi de căutare
A3: • Prima duminică din Advent 2026 = 29.11 → majoritatea târgurilor germane sunt deschise de pe 23–27.11 (Nürnberg: vineri 27.11; Viena/Köln/München: deja deschise). Verifică data exactă pe site-ul târgului.
A4: • Ryanair: folosește calendarul de tarife (Fare Finder) pe ryanair.com cu plecare OTP și perioada 26.11–01.12 – îți arată toate destinațiile cu prețul minim pe zi.
A5: • Wizz: secțiunea 'Hartă zboruri' / 'Cheap flights' pe wizzair.com, plecare București, filtru nov–dec.
A6: • Google Flights → Explore, plecare 'București', date flexibile 26.11–01.12, filtru Europa: vezi toate destinațiile pe hartă cu prețul.
A7: • Kiwi.com și azair.eu permit căutare 'oriunde' + combinații open-jaw automate.
A8: • Verifică ambele aeroporturi: Otopeni (OTP) și Băneasa (BBU) – Wizz a mutat unele rute pe Băneasa.
A9: • Prețurile low-cost nu includ bagaj de cală / troller – compară cu bagajul de care ai nevoie.
A10: • Ryanair a anunțat tăieri de rute în Germania și Franța pentru 2026 (ex. Strasbourg, Dortmund, Leipzig) – coloana 'Rută verificată?' te ajută să elimini rutele care nu mai zboară.
A11: • Memmingen e bun: München la 1h30 cu trenul (Deutschlandticket/Bayern-Ticket), Augsburg, Lindau și Neuschwanstein aproape.
